<mujoco model="b2">
  <compiler angle="radian" meshdir="assets" autolimits="true"/>

  <default>
    <default class="b2z1">
      <geom type="mesh"/>
      <joint damping="1" armature="0.1"/>
      <default class="b2_visual">
        <geom contype="0" conaffinity="0" group="2"/>
      </default>
      <default class="b2_collision">
        <geom group="3" mass="0" density="0"/>
      </default>
      <site size="0.001" rgba="0.5 0.5 0.5 0.3" group="4"/>
      <default class="z1_visual">
        <geom type="mesh" group="2" contype="0" conaffinity="0"/>
      </default>
      <default class="z1_collision">
        <geom type="cylinder" group="3" mass="0" density="0"/>
      </default>
      <default class="z1_gripper_stator_collision">
        <geom pos="0.051 0 0" type="mesh"/>
      </default>
      <default class="z1_gripper_stator_pad_collision_1">
        <geom type="box" size="0.014 0.015 0.004" pos="0.186 -0.015 -0.0125"/>
      </default>
      <default class="z1_gripper_stator_pad_collision_2">
        <geom type="box" size="0.014 0.015 0.004" pos="0.186 0.015 -0.0125"/>
      </default>
      <default class="z1_gripper_mover_collision">
        <geom type="mesh"/>
      </default>
      <default class="z1_gripper_mover_pad_collision_1">
        <geom type="box" size="0.014 0.015 0.004" pos="0.086 -0.015 -0.0055"/>
      </default>
      <default class="z1_gripper_mover_pad_collision_2">
        <geom type="box" size="0.014 0.015 0.004" pos="0.086 0.015 -0.0055"/>
      </default>
    </default>
  </default>

  <asset>
    <mesh name="base_link" file="base_link.obj"/>
    <mesh name="logo_left" file="logo_left.obj"/>
    <mesh name="logo_right" file="logo_right.obj"/>
    <mesh name="unitree_ladar" file="unitree_ladar.obj"/>
    <mesh name="f_dc_link" file="f_dc_link.obj"/>
    <mesh name="r_dc_link" file="r_dc_link.obj"/>
    <mesh name="fake_imu_link" file="fake_imu_link.STL"/>
    <mesh name="fake_head_Link" file="fake_head_Link.STL"/>
    <mesh name="fake_tail_link" file="fake_tail_link.STL"/>
    <mesh name="f_oc_link" file="f_oc_link.obj"/>
    <mesh name="r_oc_link" file="r_oc_link.obj"/>
    <mesh name="FL_hip" file="FL_hip.obj"/>
    <mesh name="FL_thigh" file="FL_thigh.obj"/>
    <mesh name="FL_thigh_protect" file="FL_thigh_protect.obj"/>
    <mesh name="FL_calf" file="FL_calf.obj"/>
    <mesh name="FL_foot" file="FL_foot.obj"/>
    <mesh name="FR_hip" file="FR_hip.obj"/>
    <mesh name="FR_thigh" file="FR_thigh.obj"/>
    <mesh name="FR_thigh_protect" file="FR_thigh_protect.obj"/>
    <mesh name="FR_calf" file="FR_calf.obj"/>
    <mesh name="FR_foot" file="FR_foot.obj"/>
    <mesh name="RL_hip" file="RL_hip.obj"/>
    <mesh name="RL_thigh" file="RL_thigh.obj"/>
    <mesh name="RL_thigh_protect" file="RL_thigh_protect.obj"/>
    <mesh name="RL_calf" file="RL_calf.obj"/>
    <mesh name="RL_foot" file="RL_foot.obj"/>
    <mesh name="RR_hip" file="RR_hip.obj"/>
    <mesh name="RR_thigh" file="RR_thigh.obj"/>
    <mesh name="RR_thigh_protect" file="RR_thigh_protect.obj"/>
    <mesh name="RR_calf" file="RR_calf.obj"/>
    <mesh name="RR_foot" file="RR_foot.obj"/>
    <mesh file="z1_Link00.stl"/>
    <mesh file="z1_Link01.stl"/>
    <mesh file="z1_Link02.stl"/>
    <mesh file="z1_Link03.stl"/>
    <mesh file="z1_Link04.stl"/>
    <mesh file="z1_Link05.stl"/>
    <mesh file="z1_Link06.stl"/>
    <mesh file="z1_GripperStator.stl"/>
    <mesh file="z1_GripperStator_col_1.stl"/>
    <mesh file="z1_GripperStator_col_2.stl"/>
    <mesh file="z1_GripperStator_col_3.stl"/>
    <mesh file="z1_GripperStator_col_4.stl"/>
    <mesh file="z1_GripperStator_col_5.stl"/>
    <mesh file="z1_GripperStator_col_6.stl"/>
    <mesh file="z1_GripperMover.stl"/>
    <mesh file="z1_GripperMover_col_1.stl"/>
    <mesh file="z1_GripperMover_col_2.stl"/>
    <mesh file="z1_GripperMover_col_3.stl"/>
    <mesh file="z1_GripperMover_col_4.stl"/>
    <mesh file="z1_GripperMover_col_5.stl"/>
  </asset>

  <worldbody>
    <body name="base_link" pos="0 0 0.8" childclass="b2z1">
      <inertial pos="0.0212868 0.0045819 0.0106169" quat="0.00178111 0.675412 -0.000262894 0.737438" mass="35.86" diaginertia="1.73786 1.66448 0.343734"/>
      <joint name="floating_base_joint" type="free"/>
      <geom type="mesh" contype="0" conaffinity="0" group="1" density="0" rgba="0.7 0.7 0.7 1" mesh="base_link"/>
      <geom size="0.25 0.14 0.075" type="box" rgba="0.7 0.7 0.7 1" class="b2_collision"/>
      <geom type="mesh" contype="0" conaffinity="0" group="1" density="0" rgba="1 1 1 1" mesh="logo_left"/>
      <geom type="mesh" contype="0" conaffinity="0" group="1" density="0" rgba="1 1 1 1" mesh="logo_right"/>
      <geom pos="0.34218 0 0.17851" type="mesh" contype="0" conaffinity="0" group="1" density="0" rgba="0.15 0.15 0.15 1" mesh="unitree_ladar"/>
      <geom size="0.076 0.08" pos="0.34218 0 0.15851" type="cylinder" rgba="0.15 0.15 0.15 1" class="b2_collision"/>
      <geom pos="0.841724 -4.57659e-06 0.130379" quat="0.00244632 3.13845e-06 0.999997 1.29099e-06" type="mesh" contype="0" conaffinity="0" group="1" density="0" rgba="0 0 0 1" mesh="f_dc_link"/>
      <geom pos="-0.378319 0.000200109 -0.379902" quat="-1.30076e-06 -0.708662 5.35065e-07 0.705548" type="mesh" contype="0" conaffinity="0" group="1" density="0" rgba="0 0 0 1" mesh="r_dc_link"/>
      <geom pos="0 -0.02341 0.04927" type="mesh" contype="0" conaffinity="0" group="1" density="0" rgba="0 0 0 1" mesh="fake_imu_link"/>
      <geom type="mesh" contype="0" conaffinity="0" group="1" density="0" rgba="0 0 0 1" mesh="fake_head_Link"/>
      <geom size="0.02 0.06 0.07" pos="0.41 0 0.005" type="box" rgba="0 0 0 1" class="b2_collision"/>
      <geom type="mesh" contype="0" conaffinity="0" group="1" density="0" rgba="0 0 0 1" mesh="fake_tail_link"/>
      <geom size="0.0125 0.06 0.07" pos="-0.405 0 0.005" type="box" rgba="0 0 0 1" class="b2_collision"/>
      <geom pos="0.84158 -0.0134347 -0.0134347" quat="-3.89602e-06 1.29867e-06 0.707107 -0.707107" type="mesh" contype="0" conaffinity="0" group="1" density="0" rgba="0 0 0 1" mesh="f_oc_link"/>
      <geom pos="-0.00451008 0.0252504 -0.0262476" quat="0.707107 -0.707107 -1.29867e-06 -1.29867e-06" type="mesh" contype="0" conaffinity="0" group="1" density="0" rgba="0 0 0 1" mesh="r_oc_link"/>
      <site name="imu" pos="0 -0.02341 0.04927"/>

      <body name="FL_hip" pos="0.3285 0.072 0">
        <inertial pos="-0.00348459 -0.00896704 0" quat="0.511347 0.510967 0.488412 0.488763" mass="2.9464" diaginertia="0.00502561 0.00397571 0.00346037"/>
        <joint name="FL_hip_joint" pos="0 0 0" axis="1 0 0" range="-0.87 0.87"/>
        <geom type="mesh" contype="0" conaffinity="0" group="1" density="0" rgba="0.7 0.7 0.7 1" mesh="FL_hip"/>
        <geom size="0.07 0.025" pos="0 0.12 0" quat="0.707107 0.707107 0 0" type="cylinder" rgba="0.7 0.7 0.7 1" class="b2_collision"/>
        <body name="FL_thigh" pos="0 0.11973 0">
          <inertial pos="-0.00592206 -0.0335174 -0.0545473" quat="0.910035 0.0855949 -0.000888135 0.405597" mass="4.8094" diaginertia="0.0640934 0.0634463 0.00699942"/>
          <joint name="FL_thigh_joint" pos="0 0 0" axis="0 1 0" range="-0.94 4.69"/>
          <geom type="mesh" contype="0" conaffinity="0" group="1" density="0" rgba="0.7 0.7 0.7 1" mesh="FL_thigh"/>
          <geom size="0.16 0.02225 0.027" pos="-0.025 0 -0.16" quat="0.707388 0 0.706825 0" type="box" rgba="0.7 0.7 0.7 1" class="b2_collision"/>
          <geom type="mesh" contype="0" conaffinity="0" group="1" density="0" rgba="0.65 0.68 0.65 1" mesh="FL_thigh_protect"/>
          <body name="FL_calf" pos="0 -8.6984e-05 -0.35">
            <inertial pos="0.00792095 0 -0.180895" quat="0.70709 -0.00488772 -0.00488772 0.70709" mass="0.53" diaginertia="0.0169205 0.0167822 0.000404298"/>
            <joint name="FL_calf_joint" pos="0 0 0" axis="0 1 0" range="-2.82 -0.43"/>
            <geom type="mesh" contype="0" conaffinity="0" group="1" density="0" rgba="0.7 0.7 0.7 1" mesh="FL_calf"/>
            <geom size="0.05 0.01225 0.009" pos="-0.002 0 -0.03" quat="0.825336 0 0.564642 0" type="box" rgba="0.7 0.7 0.7 1" class="b2_collision"/>
            <geom size="0.05 0.01225 0.009" pos="0.022 0 -0.1" quat="0.780707 0 0.624897 0" type="box" rgba="0.7 0.7 0.7 1" class="b2_collision"/>
            <geom size="0.075 0.01225 0.0075" pos="0.036 0 -0.225" quat="0.721382 0 0.692537 0" type="box" rgba="0.7 0.7 0.7 1" class="b2_collision"/>
            <geom size="0.025 0.014 0.0175" pos="0.023 0 -0.31" quat="0.540302 0 0.841471 0" type="box" rgba="0.7 0.7 0.7 1" class="b2_collision"/>
            <geom pos="0 8.6986e-05 0" type="mesh" contype="0" conaffinity="0" group="1" density="0" rgba="0.15 0.15 0.15 1" mesh="FL_foot" friction="0.4 0.005 0.0001"/>
            <geom size="0.032" pos="0 8.6986e-05 -0.35" quat="0.707388 0.706825 0 0" type="sphere" rgba="0.15 0.15 0.15 1" class="b2_collision" friction="0.4 0.005 0.0001"/>
          </body>
        </body>
      </body>

      <body name="FR_hip" pos="0.3285 -0.072 0">
        <inertial pos="-0.00844158 0.0100194 0.000239503" quat="0.476608 0.477229 0.518954 0.525151" mass="2.9464" diaginertia="0.00485575 0.00370656 0.00277186"/>
        <joint name="FR_hip_joint" pos="0 0 0" axis="1 0 0" range="-0.87 0.87"/>
        <geom type="mesh" contype="0" conaffinity="0" group="1" density="0" rgba="0.7 0.7 0.7 1" mesh="FR_hip"/>
        <geom size="0.07 0.025" pos="0 -0.12 0" quat="0.707107 0.707107 0 0" type="cylinder" rgba="0.7 0.7 0.7 1" class="b2_collision"/>
        <body name="FR_thigh" pos="0 -0.11973 0">
          <inertial pos="-0.00592206 0.0335174 -0.0545473" quat="0.40566 -0.000894103 0.0855942 0.910007" mass="4.8094" diaginertia="0.0640936 0.0634464 0.00699948"/>
          <joint name="FR_thigh_joint" pos="0 0 0" axis="0 1 0" range="-0.94 4.69"/>
          <geom type="mesh" contype="0" conaffinity="0" group="1" density="0" rgba="0.7 0.7 0.7 1" mesh="FR_thigh"/>
          <geom size="0.125 0.014 0.02" pos="-0.03 0 -0.2" quat="0.707388 0 0.706825 0" type="box" rgba="0.7 0.7 0.7 1" class="b2_collision"/>
          <geom type="mesh" contype="0" conaffinity="0" group="1" density="0" rgba="0.65 0.68 0.65 1" mesh="FR_thigh_protect"/>
          <body name="FR_calf" pos="0 8.6986e-05 -0.35">
            <inertial pos="0.00792095 0 -0.180895" quat="0.70709 -0.00488772 -0.00488772 0.70709" mass="0.53" diaginertia="0.0169205 0.0167822 0.000404298"/>
            <joint name="FR_calf_joint" pos="0 0 0" axis="0 1 0" range="-2.82 -0.43"/>
            <geom type="mesh" contype="0" conaffinity="0" group="1" density="0" rgba="0.7 0.7 0.7 1" mesh="FR_calf"/>
            <geom size="0.05 0.01225 0.009" pos="-0.002 0 -0.03" quat="0.825336 0 0.564642 0" type="box" rgba="0.7 0.7 0.7 1" class="b2_collision"/>
            <geom size="0.05 0.01225 0.009" pos="0.022 0 -0.1" quat="0.780707 0 0.624897 0" type="box" rgba="0.7 0.7 0.7 1" class="b2_collision"/>
            <geom size="0.075 0.01225 0.0075" pos="0.036 0 -0.225" quat="0.721382 0 0.692537 0" type="box" rgba="0.7 0.7 0.7 1" class="b2_collision"/>
            <geom size="0.025 0.014 0.0175" pos="0.023 0 -0.31" quat="0.540302 0 0.841471 0" type="box" rgba="0.7 0.7 0.7 1" class="b2_collision"/>
            <geom type="mesh" contype="0" conaffinity="0" group="1" density="0" rgba="0.15 0.15 0.15 1" mesh="FR_foot" friction="0.4 0.005 0.0001"/>
            <geom size="0.032" pos="0 8.6986e-05 -0.35" quat="0.707388 0.706825 0 0" type="sphere" rgba="0.15 0.15 0.15 1" class="b2_collision" friction="0.4 0.005 0.0001"/>
          </body>
        </body>
      </body>

      <body name="RL_hip" pos="-0.3285 0.072 0">
        <inertial pos="0.00844158 -0.0100194 0.000239503" quat="0.477229 0.476608 0.525151 0.518954" mass="2.9464" diaginertia="0.00485575 0.00370656 0.00277186"/>
        <joint name="RL_hip_joint" pos="0 0 0" axis="1 0 0" range="-0.87 0.87"/>
        <geom type="mesh" contype="0" conaffinity="0" group="1" density="0" rgba="0.7 0.7 0.7 1" mesh="RL_hip"/>
        <geom size="0.07 0.025" pos="0 0.12 0" quat="0.707107 0.707107 0 0" type="cylinder" rgba="0.7 0.7 0.7 1" class="b2_collision"/>
        <body name="RL_thigh" pos="0 0.11973 0">
          <inertial pos="-0.00592206 -0.0335174 -0.0545473" quat="0.910007 0.0855942 -0.000894103 0.40566" mass="4.8094" diaginertia="0.0640936 0.0634464 0.00699948"/>
          <joint name="RL_thigh_joint" pos="0 0 0" axis="0 1 0" range="-0.94 4.69"/>
          <geom type="mesh" contype="0" conaffinity="0" group="1" density="0" rgba="0.7 0.7 0.7 1" mesh="RL_thigh"/>
          <geom size="0.125 0.014 0.02" pos="-0.03 0 -0.2" quat="0.707388 0 0.706825 0" type="box" rgba="0.7 0.7 0.7 1" class="b2_collision"/>
          <geom type="mesh" contype="0" conaffinity="0" group="1" density="0" rgba="0.65 0.68 0.65 1" mesh="RL_thigh_protect"/>
          <body name="RL_calf" pos="0 -8.6984e-05 -0.35">
            <inertial pos="0.00792095 0 -0.180895" quat="0.70709 -0.00488772 -0.00488772 0.70709" mass="0.53" diaginertia="0.0169205 0.0167822 0.000404298"/>
            <joint name="RL_calf_joint" pos="0 0 0" axis="0 1 0" range="-2.82 -0.43"/>
            <geom type="mesh" contype="0" conaffinity="0" group="1" density="0" rgba="0.7 0.7 0.7 1" mesh="RL_calf"/>
            <geom size="0.05 0.01225 0.009" pos="-0.002 0 -0.03" quat="0.825336 0 0.564642 0" type="box" rgba="0.7 0.7 0.7 1" class="b2_collision"/>
            <geom size="0.05 0.01225 0.009" pos="0.022 0 -0.1" quat="0.780707 0 0.624897 0" type="box" rgba="0.7 0.7 0.7 1" class="b2_collision"/>
            <geom size="0.075 0.01225 0.0075" pos="0.036 0 -0.225" quat="0.721382 0 0.692537 0" type="box" rgba="0.7 0.7 0.7 1" class="b2_collision"/>
            <geom size="0.025 0.014 0.0175" pos="0.023 0 -0.31" quat="0.540302 0 0.841471 0" type="box" rgba="0.7 0.7 0.7 1" class="b2_collision"/>
            <geom pos="0 8.6986e-05 0" type="mesh" contype="0" conaffinity="0" group="1" density="0" rgba="0.15 0.15 0.15 1" mesh="RL_foot" friction="0.4 0.005 0.0001"/>
            <geom size="0.032" pos="0 8.6986e-05 -0.35" quat="0.707388 0.706825 0 0" type="sphere" rgba="0.15 0.15 0.15 1" class="b2_collision" friction="0.4 0.005 0.0001"/>
          </body>
        </body>
      </body>

      <body name="RR_hip" pos="-0.3285 -0.072 0">
        <inertial pos="0.00348459 0.00896704 0" quat="0.510967 0.511347 0.488763 0.488412" mass="2.9464" diaginertia="0.00502561 0.00397571 0.00346037"/>
        <joint name="RR_hip_joint" pos="0 0 0" axis="1 0 0" range="-0.87 0.87"/>
        <geom type="mesh" contype="0" conaffinity="0" group="1" density="0" rgba="0.7 0.7 0.7 1" mesh="RR_hip"/>
        <geom size="0.07 0.025" pos="0 -0.12 0" quat="0.707107 0.707107 0 0" type="cylinder" rgba="0.7 0.7 0.7 1" class="b2_collision"/>
        <body name="RR_thigh" pos="0 -0.11973 0">
          <inertial pos="-0.00592206 0.0335174 -0.0545473" quat="0.405597 -0.000888135 0.0855949 0.910035" mass="4.8094" diaginertia="0.0640934 0.0634463 0.00699942"/>
          <joint name="RR_thigh_joint" pos="0 0 0" axis="0 1 0" range="-0.94 4.69"/>
          <geom type="mesh" contype="0" conaffinity="0" group="1" density="0" rgba="0.7 0.7 0.7 1" mesh="RR_thigh"/>
          <geom size="0.125 0.014 0.02" pos="-0.03 0 -0.2" quat="0.707388 0 0.706825 0" type="box" rgba="0.7 0.7 0.7 1" class="b2_collision"/>
          <geom type="mesh" contype="0" conaffinity="0" group="1" density="0" rgba="0.65 0.68 0.65 1" mesh="RR_thigh_protect"/>
          <body name="RR_calf" pos="0 8.6986e-05 -0.35">
            <inertial pos="0.00792095 0 -0.180895" quat="0.70709 -0.00488772 -0.00488772 0.70709" mass="0.53" diaginertia="0.0169205 0.0167822 0.000404298"/>
            <joint name="RR_calf_joint" pos="0 0 0" axis="0 1 0" range="-2.82 -0.43"/>
            <geom type="mesh" contype="0" conaffinity="0" group="1" density="0" rgba="0.7 0.7 0.7 1" mesh="RR_calf"/>
            <geom size="0.05 0.01225 0.009" pos="-0.002 0 -0.03" quat="0.825336 0 0.564642 0" type="box" rgba="0.7 0.7 0.7 1" class="b2_collision"/>
            <geom size="0.05 0.01225 0.009" pos="0.022 0 -0.1" quat="0.780707 0 0.624897 0" type="box" rgba="0.7 0.7 0.7 1" class="b2_collision"/>
            <geom size="0.075 0.01225 0.0075" pos="0.036 0 -0.225" quat="0.721382 0 0.692537 0" type="box" rgba="0.7 0.7 0.7 1" class="b2_collision"/>
            <geom size="0.025 0.014 0.0175" pos="0.023 0 -0.31" quat="0.540302 0 0.841471 0" type="box" rgba="0.7 0.7 0.7 1" class="b2_collision"/>
            <geom pos="0 -8.6984e-05 0" type="mesh" contype="0" conaffinity="0" group="1" density="0" rgba="0.15 0.15 0.15 1" mesh="RR_foot" friction="0.4 0.005 0.0001"/>
            <geom size="0.032" pos="0 8.6986e-05 -0.35" quat="0.707388 0.706825 0 0" type="sphere" rgba="0.15 0.15 0.15 1" class="b2_collision" friction="0.4 0.005 0.0001"/>
          </body>
        </body>
      </body>

      <body name="link00" pos="0.08 0 0.08">
        <inertial pos="-0.00334984 -0.00013615 0.0249584" quat="-0.00692194 0.682592 0.00133293 0.730766" mass="0.472475" diaginertia="0.000531375 0.000415207 0.000378658"/>
        <geom class="z1_visual" mesh="z1_Link00"/>
        <geom size="0.0325 0.0255" pos="0 0 0.0255" class="z1_collision"/>
        <body name="link01" pos="0 0 0.0585">
          <inertial pos="2.47e-06 -0.00025198 0.0231717" quat="0.708578 0.705633 0.000281462 -0.000355927" mass="0.673326" diaginertia="0.00128328 0.000839362 0.000719308"/>
          <joint name="joint1" axis="0 0 1" range="-2.61799 2.61799"/>
          <geom class="z1_visual" mesh="z1_Link01"/>
          <body name="link02" pos="0 0 0.045">
            <inertial pos="-0.110126 0.00240029 0.00158266" quat="0.00748058 0.707092 -0.0114473 0.70699" mass="1.19132" diaginertia="0.0246612 0.0243113 0.00100468"/>
            <joint name="joint2" axis="0 1 0" range="0 2.96706" damping="2"/>
            <geom class="z1_visual" mesh="z1_Link02"/>
            <geom size="0.0325 0.051" quat="1 1 0 0" class="z1_collision"/>
            <geom size="0.0225 0.1175" pos="-0.1625 0 0" quat="1 0 1 0" class="z1_collision"/>
            <geom size="0.0325 0.0255" pos="-0.35 0 0" quat="1 1 0 0" class="z1_collision"/>
            <body name="link03" pos="-0.35 0 0">
              <inertial pos="0.106092 -0.00541815 0.0347638" quat="0.540557 0.443575 0.426319 0.573839" mass="0.839409" diaginertia="0.00954365 0.00938711 0.000558432"/>
              <joint name="joint3" axis="0 1 0" range="-2.87979 0"/>
              <geom class="z1_visual" mesh="z1_Link03"/>
              <geom size="0.02 0.058" pos="0.128 0 0.055" quat="1 0 1 0" class="z1_collision"/>
              <geom size="0.0325 0.0295" pos="0.2205 0 0.055" quat="0.5 -0.5 0.5 0.5" class="z1_collision"/>
              <body name="link04" pos="0.218 0 0.057">
                <inertial pos="0.0436668 0.00364738 -0.00170192" quat="0.0390835 0.726445 -0.0526787 0.684087" mass="0.564046" diaginertia="0.000981656 0.00094053 0.000302655"/>
                <joint name="joint4" axis="0 1 0" range="-1.51844 1.51844"/>
                <geom class="z1_visual" mesh="z1_Link04"/>
                <geom size="0.0325 0.0335" pos="0.072 0 0" class="z1_collision"/>
                <body name="link05" pos="0.07 0 0">
                  <inertial pos="0.0312153 0 0.00646316" quat="0.462205 0.535209 0.53785 0.45895" mass="0.389385" diaginertia="0.000558961 0.000547317 0.000167332"/>
                  <joint name="joint5" axis="0 0 1" range="-1.3439 1.3439"/>
                  <geom class="z1_visual" mesh="z1_Link05"/>
                  <body name="link06" pos="0.0492 0 0">
                    <inertial pos="0.0241569 -0.00017355 -0.00143876" quat="0.998779 0.0457735 -0.00663717 0.0173548" mass="0.288758" diaginertia="0.00018333 0.000147464 0.000146786"/>
                    <joint name="joint6" axis="1 0 0" range="-2.79253 2.79253"/>
                    <geom class="z1_visual" mesh="z1_Link06"/>
                    <geom size="0.0325 0.0255" pos="0.0255 0 0" quat="1 0 1 0" class="z1_collision"/>
                    <geom pos="0.051 0 0" type="mesh" mesh="z1_GripperStator" class="z1_visual"/>
                    <geom class="z1_gripper_stator_collision" mesh="z1_GripperStator_col_1"/>
                    <geom class="z1_gripper_stator_collision" mesh="z1_GripperStator_col_2"/>
                    <geom class="z1_gripper_stator_collision" mesh="z1_GripperStator_col_3"/>
                    <geom class="z1_gripper_stator_collision" mesh="z1_GripperStator_col_4"/>
                    <geom class="z1_gripper_stator_collision" mesh="z1_GripperStator_col_5"/>
                    <geom class="z1_gripper_stator_collision" mesh="z1_GripperStator_col_6"/>
                    <geom class="z1_gripper_stator_pad_collision_1"/>
                    <geom class="z1_gripper_stator_pad_collision_2"/>
                    <body name="gripperMover" pos="0.1 0 0">
                      <inertial pos="0.0132063 0.00476708 0.00380534" quat="0.0631093 0.669067 -0.0615783 0.737953" mass="0.276213" diaginertia="0.000359044 0.000270888 0.000172378"/>
                      <joint name="jointGripper" axis="0 1 0" range="-1.51844 0"/>
                      <geom type="mesh" mesh="z1_GripperMover" class="z1_visual"/>
                      <geom class="z1_gripper_mover_collision" mesh="z1_GripperMover_col_1"/>
                      <geom class="z1_gripper_mover_collision" mesh="z1_GripperMover_col_2"/>
                      <geom class="z1_gripper_mover_collision" mesh="z1_GripperMover_col_3"/>
                      <geom class="z1_gripper_mover_collision" mesh="z1_GripperMover_col_4"/>
                      <geom class="z1_gripper_mover_collision" mesh="z1_GripperMover_col_5"/>
                      <geom class="z1_gripper_mover_pad_collision_1"/>
                      <geom class="z1_gripper_mover_pad_collision_2"/>
                    </body>
                  </body>
                </body>
              </body>
            </body>
          </body>
        </body>
      </body>

    </body>
  </worldbody>

  <actuator>
    <!-- <position name="FL_hip" joint="FL_hip_joint" kp="100" dampratio="1"/>
    <position name="FL_thigh" joint="FL_thigh_joint" kp="100" dampratio="1"/>
    <position name="FL_calf" joint="FL_calf_joint" kp="100" dampratio="1"/>
    <position name="FR_hip" joint="FR_hip_joint" kp="100" dampratio="1"/>
    <position name="FR_thigh" joint="FR_thigh_joint" kp="100" dampratio="1"/>
    <position name="FR_calf" joint="FR_calf_joint" kp="100" dampratio="1"/>
    <position name="RL_hip" joint="RL_hip_joint" kp="100" dampratio="1"/>
    <position name="RL_thigh" joint="RL_thigh_joint" kp="100" dampratio="1"/>
    <position name="RL_calf" joint="RL_calf_joint" kp="100" dampratio="1"/>
    <position name="RR_hip" joint="RR_hip_joint" kp="100" dampratio="1"/>
    <position name="RR_thigh" joint="RR_thigh_joint" kp="100" dampratio="1"/>
    <position name="RR_calf" joint="RR_calf_joint" kp="100" dampratio="1"/>  -->

    <!-- ARM-->
    <position name="arm_joint1" joint="joint1" kp="100" dampratio="1"/>
    <position name="arm_joint2" joint="joint2" kp="100" dampratio="1"/>
    <position name="arm_joint3" joint="joint3" kp="100" dampratio="1"/>
    <position name="arm_joint4" joint="joint4" kp="100" dampratio="1"/>
    <position name="arm_joint5" joint="joint5" kp="100" dampratio="1"/>
    <position name="arm_joint6" joint="joint6" kp="100" dampratio="1"/>

    <!-- gripper -->
    <!-- <position name="gripper" joint="jointGripper" kp="100" dampratio="1"/> -->
</actuator>

  <contact>
    <exclude body1="base_link" body2="FL_thigh"/>
    <exclude body1="base_link" body2="FR_thigh"/>
    <exclude body1="base_link" body2="RL_thigh"/>
    <exclude body1="base_link" body2="RR_thigh"/>
  </contact>

  <sensor>
    <gyro name="imu_ang_vel" site="imu"/>
    <velocimeter name="imu_lin_vel" site="imu"/>
    <accelerometer name="imu_lin_acc" site="imu"/>
  </sensor>

  <keyframe>
    <key name="home" qpos="0 0 0.5 1 0 0 0 0 1.28 -2.84 0 1.28 -2.84 0 1.28 -2.84 0 1.28 -2.84"
      ctrl="0 1.28 -2.84 0 1.28 -2.84 0 1.28 -2.84 0 1.28 -2.84"/>
  </keyframe>

</mujoco>